<?xml version="1.0" ?>
<robot name="kuka_iiwa14">
    <!-- MATERIALS -->
    <material name="Black">
        <color rgba="0.0 0.0 0.0 1.0" />
    </material>
    <material name="Blue">
        <color rgba="0.0 0.0 0.8 1.0" />
    </material>
    <material name="Green">
        <color rgba="0.0 0.8 0.0 1.0" />
    </material>
    <material name="Grey">
        <color rgba="0.4 0.4 0.4 1.0" />
    </material>
    <material name="Orange">
        <color rgba="1.0 0.4235294117647059 0.0392156862745098 1.0" />
    </material>
    <material name="Brown">
        <color rgba="0.8705882352941177 0.8117647058823529 0.7647058823529411 1.0" />
    </material>
    <material name="Red">
        <color rgba="0.8 0.0 0.0 1.0" />
    </material>
    <material name="White">
        <color rgba="1.0 1.0 1.0 1.0" />
    </material>
    <!-- ROBOT -->
    <link name="world" />
    <!--joint between {parent} and link_0-->
    <joint name="world_iiwa_joint" type="fixed">
        <origin rpy="0 0 0" xyz="0 0 0" />
        <parent link="world" />
        <child link="iiwa_link_0" />
    </joint>
    <link name="iiwa_link_0">
        <inertial>
            <origin rpy="0 0 0" xyz="-0.1 0 0.07" />
            <mass value="5" />
            <inertia ixx="0.05" ixy="0" ixz="0" iyy="0.06" iyz="0" izz="0.03" />
        </inertial>
        <visual>
            <origin rpy="0 0 0" xyz="0 0 0" />
            <geometry>
                <mesh filename="package://air_hockey/mesh/visual/link_0.stl" />
            </geometry>
            <material name="Grey" />
        </visual>
        <collision>
            <origin rpy="0 0 0" xyz="0 0 0" />
            <geometry>
                <mesh filename="package://air_hockey/mesh/collision/link_0.stl" />
            </geometry>
            <material name="Grey" />
        </collision>
        <self_collision_checking>
            <origin rpy="0 0 0" xyz="0 0 0" />
            <geometry>
                <capsule length="0.25" radius="0.15" />
            </geometry>
        </self_collision_checking>
    </link>
    <!-- joint between link_0 and link_1 -->
    <joint name="iiwa_joint_1" type="revolute">
        <parent link="iiwa_link_0" />
        <child link="iiwa_link_1" />
        <origin rpy="0 0 0" xyz="0 0 0.1575" />
        <axis xyz="0 0 1" />
        <limit effort="300" lower="-2.9670597283903604" upper="2.9670597283903604" velocity="10" />
        <safety_controller k_position="100" k_velocity="2" soft_lower_limit="-2.9321531433504737" soft_upper_limit="2.9321531433504737" />
        <dynamics damping="0.5" />
    </joint>
    <link name="iiwa_link_1">
        <inertial>
            <origin rpy="0 0 0" xyz="0 -0.03 0.12" />
            <mass value="4" />
            <inertia ixx="0.1" ixy="0" ixz="0" iyy="0.09" iyz="0" izz="0.02" />
        </inertial>
        <visual>
            <origin rpy="0 0 0" xyz="0 0 0" />
            <geometry>
                <mesh filename="package://air_hockey/mesh/visual/link_1.stl" />
            </geometry>
            <material name="Orange" />
        </visual>
        <collision>
            <origin rpy="0 0 0" xyz="0 0 0" />
            <geometry>
                <mesh filename="package://air_hockey/mesh/collision/link_1.stl" />
            </geometry>
            <material name="Orange" />
        </collision>
    </link>
    <!-- joint between link_1 and link_2 -->
    <joint name="iiwa_joint_2" type="revolute">
        <parent link="iiwa_link_1" />
        <child link="iiwa_link_2" />
        <origin rpy="1.5707963267948966   0 3.141592653589793" xyz="0 0 0.2025" />
        <axis xyz="0 0 1" />
        <limit effort="300" lower="-2.0943951023931953" upper="2.0943951023931953" velocity="10" />
        <safety_controller k_position="100" k_velocity="2" soft_lower_limit="-2.0594885173533086" soft_upper_limit="2.0594885173533086" />
        <dynamics damping="0.5" />
    </joint>
    <link name="iiwa_link_2">
        <inertial>
            <origin rpy="0 0 0" xyz="0.0003 0.059 0.042" />
            <mass value="4" />
            <inertia ixx="0.05" ixy="0" ixz="0" iyy="0.018" iyz="0" izz="0.044" />
        </inertial>
        <visual>
            <origin rpy="0 0 0" xyz="0 0 0" />
            <geometry>
                <mesh filename="package://air_hockey/mesh/visual/link_2.stl" />
            </geometry>
            <material name="Orange" />
        </visual>
        <collision>
            <origin rpy="0 0 0" xyz="0 0 0" />
            <geometry>
                <mesh filename="package://air_hockey/mesh/collision/link_2.stl" />
            </geometry>
            <material name="Orange" />
        </collision>
    </link>
    <!-- joint between link_2 and link_3 -->
    <joint name="iiwa_joint_3" type="revolute">
        <parent link="iiwa_link_2" />
        <child link="iiwa_link_3" />
        <origin rpy="1.5707963267948966 0 3.141592653589793" xyz="0 0.2045 0" />
        <axis xyz="0 0 1" />
        <limit effort="300" lower="-2.9670597283903604" upper="2.9670597283903604" velocity="10" />
        <safety_controller k_position="100" k_velocity="2" soft_lower_limit="-2.9321531433504737" soft_upper_limit="2.9321531433504737" />
        <dynamics damping="0.5" />
    </joint>
    <link name="iiwa_link_3">
        <inertial>
            <origin rpy="0 0 0" xyz="0 0.03 0.13" />
            <mass value="3" />
            <inertia ixx="0.08" ixy="0" ixz="0" iyy="0.075" iyz="0" izz="0.01" />
        </inertial>
        <visual>
            <origin rpy="0 0 0" xyz="0 0 0" />
            <geometry>
                <mesh filename="package://air_hockey/mesh/visual/link_3.stl" />
            </geometry>
            <material name="Orange" />
        </visual>
        <collision>
            <origin rpy="0 0 0" xyz="0 0 0" />
            <geometry>
                <mesh filename="package://air_hockey/mesh/collision/link_3.stl" />
            </geometry>
            <material name="Orange" />
        </collision>
    </link>
    <!-- joint between link_3 and link_4 -->
    <joint name="iiwa_joint_4" type="revolute">
        <parent link="iiwa_link_3" />
        <child link="iiwa_link_4" />
        <origin rpy="1.5707963267948966 0 0" xyz="0 0 0.2155" />
        <axis xyz="0 0 1" />
        <limit effort="300" lower="-2.0943951023931953" upper="2.0943951023931953" velocity="10" />
        <safety_controller k_position="100" k_velocity="2" soft_lower_limit="-2.0594885173533086" soft_upper_limit="2.0594885173533086" />
        <dynamics damping="0.5" />
    </joint>
    <link name="iiwa_link_4">
        <inertial>
            <origin rpy="0 0 0" xyz="0 0.067 0.034" />
            <mass value="2.7" />
            <inertia ixx="0.03" ixy="0" ixz="0" iyy="0.01" iyz="0" izz="0.029" />
        </inertial>
        <visual>
            <origin rpy="0 0 0" xyz="0 0 0" />
            <geometry>
                <mesh filename="package://air_hockey/mesh/visual/link_4.stl" />
            </geometry>
            <material name="Orange" />
        </visual>
        <collision>
            <origin rpy="0 0 0" xyz="0 0 0" />
            <geometry>
                <mesh filename="package://air_hockey/mesh/collision/link_4.stl" />
            </geometry>
            <material name="Orange" />
        </collision>
    </link>
    <!-- joint between link_4 and link_5 -->
    <joint name="iiwa_joint_5" type="revolute">
        <parent link="iiwa_link_4" />
        <child link="iiwa_link_5" />
        <origin rpy="-1.5707963267948966 3.141592653589793 0" xyz="0 0.1845 0" />
        <axis xyz="0 0 1" />
        <limit effort="300" lower="-2.9670597283903604" upper="2.9670597283903604" velocity="10" />
        <safety_controller k_position="100" k_velocity="2" soft_lower_limit="-2.9321531433504737" soft_upper_limit="2.9321531433504737" />
        <dynamics damping="0.5" />
    </joint>
    <link name="iiwa_link_5">
        <inertial>
            <origin rpy="0 0 0" xyz="0.0001 0.021 0.076" />
            <mass value="1.7" />
            <inertia ixx="0.02" ixy="0" ixz="0" iyy="0.018" iyz="0" izz="0.005" />
        </inertial>
        <visual>
            <origin rpy="0 0 0" xyz="0 0 0" />
            <geometry>
                <mesh filename="package://air_hockey/mesh/visual/link_5.stl" />
            </geometry>
            <material name="Orange" />
        </visual>
        <collision>
            <origin rpy="0 0 0" xyz="0 0 0" />
            <geometry>
                <mesh filename="package://air_hockey/mesh/collision/link_5.stl" />
            </geometry>
            <material name="Orange" />
        </collision>
    </link>
    <!-- joint between link_5 and link_6 -->
    <joint name="iiwa_joint_6" type="revolute">
        <parent link="iiwa_link_5" />
        <child link="iiwa_link_6" />
        <origin rpy="1.5707963267948966 0 0" xyz="0 0 0.2155" />
        <axis xyz="0 0 1" />
        <limit effort="300" lower="-2.0943951023931953" upper="2.0943951023931953" velocity="10" />
        <safety_controller k_position="100" k_velocity="2" soft_lower_limit="-2.0594885173533086" soft_upper_limit="2.0594885173533086" />
        <dynamics damping="0.5" />
    </joint>
    <link name="iiwa_link_6">
        <inertial>
            <origin rpy="0 0 0" xyz="0 0.0006 0.0004" />
            <mass value="1.8" />
            <inertia ixx="0.005" ixy="0" ixz="0" iyy="0.0036" iyz="0" izz="0.0047" />
        </inertial>
        <visual>
            <origin rpy="0 0 0" xyz="0 0 0" />
            <geometry>
                <mesh filename="package://air_hockey/mesh/visual/link_6.stl" />
            </geometry>
            <material name="Orange" />
        </visual>
        <collision>
            <origin rpy="0 0 0" xyz="0 0 0" />
            <geometry>
                <mesh filename="package://air_hockey/mesh/collision/link_6.stl" />
            </geometry>
            <material name="Orange" />
        </collision>
    </link>
    <!-- joint between link_6 and link_7 -->
    <joint name="iiwa_joint_7" type="revolute">
        <parent link="iiwa_link_6" />
        <child link="iiwa_link_7" />
        <origin rpy="-1.5707963267948966 3.141592653589793 0" xyz="0 0.081 0" />
        <axis xyz="0 0 1" />
        <limit effort="300" lower="-3.0543261909900763" upper="3.0543261909900763" velocity="10" />
        <safety_controller k_position="100" k_velocity="2" soft_lower_limit="-3.01941960595019" soft_upper_limit="3.01941960595019" />
        <dynamics damping="0.5" />
    </joint>
    <link name="iiwa_link_7">
        <inertial>
            <origin rpy="0 0 0" xyz="0 0 0.02" />
            <mass value="0.3" />
            <inertia ixx="0.001" ixy="0" ixz="0" iyy="0.001" iyz="0" izz="0.001" />
        </inertial>
        <visual>
            <origin rpy="0 0 0" xyz="0 0 0" />
            <geometry>
                <mesh filename="package://air_hockey/mesh/visual/link_7.stl" />
            </geometry>
            <material name="Grey" />
        </visual>
        <collision>
            <origin rpy="0 0 0" xyz="0 0 0" />
            <geometry>
                <mesh filename="package://air_hockey/mesh/collision/link_7.stl" />
            </geometry>
            <material name="Grey" />
        </collision>
    </link>
    <!-- POLE -->
    <joint name="fixed_pole_joint" type="fixed">
        <parent link="iiwa_link_7" />
        <child link="pole" />
        <origin rpy="0 0 0" xyz="0 0 0.23" />
    </joint>
    <link name="pole">
        <inertial>
            <origin rpy="0 0 0" xyz="0 0 0" />
            <mass value="0.3" />
            <inertia ixx="0.007" ixy="0" ixz="0" iyy="0.007" iyz="0" izz="0.007" />
        </inertial>
        <visual>
            <origin rpy="0 0 0" xyz="0 0 0" />
            <geometry>
                <cylinder length="0.4" radius="0.015" />
            </geometry>
            <material name="Grey" />
        </visual>
        <collision>
            <origin rpy="0 0 0" xyz="0 0 0" />
            <geometry>
                <cylinder length="0.4" radius="0.015" />
            </geometry>
        </collision>
    </link>
    <!-- Ball x -->
    <!-- Revolute joint on X-axis -->
    <joint name="ball_joint_x" type="revolute">
        <parent link="pole" />
        <child link="ball_link_1" />
        <origin rpy="0 0 0" xyz="0 0 0.21" />
        <axis xyz="1 0 0" />
        <!-- Rotation around X-axis -->
        <limit effort="300" lower="-1.5708" upper="1.5708" velocity="10" />
    </joint>
    <link name="ball_link_1">
        <inertial>
            <mass value="0.001" />
            <!-- Very small mass to minimize impact -->
            <inertia ixx="0.0001" ixy="0.0" ixz="0.0" iyy="0.0001" iyz="0.0" izz="0.0001" />
            <origin rpy="0 0 0" xyz="0 0 0" />
        </inertial>
        <visual>
            <origin rpy="0 0 0" xyz="0 0 0" />
            <geometry>
                <sphere radius="0.03" />
            </geometry>
            <material name="Green" />
        </visual>
        <collision>
            <origin rpy="0 0 0" xyz="0 0 0" />
            <geometry>
                <sphere radius="0.03" />
            </geometry>
        </collision>
    </link>
    <!-- Ball y-->
    <!-- Revolute joint on Y-axis -->
    <joint name="ball_joint_y" type="revolute">
        <parent link="ball_link_1" />
        <child link="ball_link_2" />
        <origin rpy="0 0 0" xyz="0 0 0" />
        <axis xyz="0 1 0" />
        <!-- Rotation around Y-axis -->
        <limit effort="300" lower="-1.5708" upper="1.5708" velocity="10" />
    </joint>
    <link name="ball_link_2">
        <inertial>
            <mass value="0.001" />
            <inertia ixx="0.0001" ixy="0.0" ixz="0.0" iyy="0.0001" iyz="0.0" izz="0.0001" />
        </inertial>
    </link>
    <!-- MALLET -->
    <joint name="fixed_mallet_joint" type="fixed">
        <parent link="ball_link_2" />
        <child link="mallet" />
        <origin rpy="0 0 0.03" xyz="0 0 0" />
    </joint>
    <!-- Link for the mallet -->
    <link name="mallet">
        <inertial>
            <origin rpy="0 0 0" xyz="0 0 0.03" />
            <mass value="0.2" />
            <inertia ixx="0.005" ixy="0" ixz="0" iyy="0.005" iyz="0" izz="0.005" />
        </inertial>
        <visual>
            <origin rpy="0 0 0" xyz="0 0 0.03" />
            <geometry>
                <cylinder length="0.05" radius="0.05" />
            </geometry>
            <material name="Blue" />
        </visual>
        <collision>
            <origin rpy="0 0 0" xyz="0 0 0.03" />
            <geometry>
                <cylinder length="0.05" radius="0.05" />
            </geometry>
        </collision>
    </link>
    <gazebo>
        <plugin name="gazebo_ros_control" filename="libgazebo_ros_control.so">
            <robotNamespace>/</robotNamespace>
        </plugin>
    </gazebo>
    <transmission name="trans_iiwa_joint_1">
        <type>transmission_interface/SimpleTransmission</type>
        <joint name="iiwa_joint_1">
            <hardwareInterface>hardware_interface/VelocityJointInterface</hardwareInterface>
        </joint>
        <actuator name="iiwa_joint_1_motor">
            <hardwareInterface>hardware_interface/VelocityJointInterface</hardwareInterface>
            <mechanicalReduction>1</mechanicalReduction>
        </actuator>
    </transmission>
    <transmission name="trans_iiwa_joint_2">
        <type>transmission_interface/SimpleTransmission</type>
        <joint name="iiwa_joint_2">
            <hardwareInterface>hardware_interface/VelocityJointInterface</hardwareInterface>
        </joint>
        <actuator name="iiwa_joint_2_motor">
            <hardwareInterface>hardware_interface/VelocityJointInterface</hardwareInterface>
            <mechanicalReduction>1</mechanicalReduction>
        </actuator>
    </transmission>
    <transmission name="trans_iiwa_joint_3">
        <type>transmission_interface/SimpleTransmission</type>
        <joint name="iiwa_joint_3">
            <hardwareInterface>hardware_interface/VelocityJointInterface</hardwareInterface>
        </joint>
        <actuator name="iiwa_joint_3_motor">
            <hardwareInterface>hardware_interface/VelocityJointInterface</hardwareInterface>
            <mechanicalReduction>1</mechanicalReduction>
        </actuator>
    </transmission>
    <transmission name="trans_iiwa_joint_4">
        <type>transmission_interface/SimpleTransmission</type>
        <joint name="iiwa_joint_4">
            <hardwareInterface>hardware_interface/VelocityJointInterface</hardwareInterface>
        </joint>
        <actuator name="iiwa_joint_4_motor">
            <hardwareInterface>hardware_interface/VelocityJointInterface</hardwareInterface>
            <mechanicalReduction>1</mechanicalReduction>
        </actuator>
    </transmission>
    <transmission name="trans_iiwa_joint_5">
        <type>transmission_interface/SimpleTransmission</type>
        <joint name="iiwa_joint_5">
            <hardwareInterface>hardware_interface/VelocityJointInterface</hardwareInterface>
        </joint>
        <actuator name="iiwa_joint_5_motor">
            <hardwareInterface>hardware_interface/VelocityJointInterface</hardwareInterface>
            <mechanicalReduction>1</mechanicalReduction>
        </actuator>
    </transmission>
    <transmission name="trans_iiwa_joint_6">
        <type>transmission_interface/SimpleTransmission</type>
        <joint name="iiwa_joint_6">
            <hardwareInterface>hardware_interface/VelocityJointInterface</hardwareInterface>
        </joint>
        <actuator name="iiwa_joint_6_motor">
            <hardwareInterface>hardware_interface/VelocityJointInterface</hardwareInterface>
            <mechanicalReduction>1</mechanicalReduction>
        </actuator>
    </transmission>
    <transmission name="trans_iiwa_joint_7">
        <type>transmission_interface/SimpleTransmission</type>
        <joint name="iiwa_joint_7">
            <hardwareInterface>hardware_interface/VelocityJointInterface</hardwareInterface>
        </joint>
        <actuator name="iiwa_joint_7_motor">
            <hardwareInterface>hardware_interface/VelocityJointInterface</hardwareInterface>
            <mechanicalReduction>1</mechanicalReduction>
        </actuator>
    </transmission>
    <transmission name="trans_ball_joint_x">
        <type>transmission_interface/SimpleTransmission</type>
        <joint name="ball_joint_x">
            <hardwareInterface>hardware_interface/VelocityJointInterface</hardwareInterface>
        </joint>
        <actuator name="ball_joint_x_motor">
            <hardwareInterface>hardware_interface/VelocityJointInterface</hardwareInterface>
            <mechanicalReduction>1</mechanicalReduction>
        </actuator>
    </transmission>
    <transmission name="trans_ball_joint_y">
        <type>transmission_interface/SimpleTransmission</type>
        <joint name="ball_joint_y">
            <hardwareInterface>hardware_interface/VelocityJointInterface</hardwareInterface>
        </joint>
        <actuator name="ball_joint_y_motor">
            <hardwareInterface>hardware_interface/VelocityJointInterface</hardwareInterface>
            <mechanicalReduction>1</mechanicalReduction>
        </actuator>
    </transmission>
</robot>

