<robot name="simple_arm">
    <link name="base_link">
        <visual>
            <geometry>
                <box size="0.5 0.5 0.2"/>
            </geometry>
            <material name="green"/>
        </visual>
    </link>
    <joint name="joint1" type="continuous">
        <parent link="base_link"/>
        <child link="link1"/>
        <origin xyz="0 0 0.1" rpy="0 0 0"/>
        <axis xyz="0 0 1"/>
    </joint>
    <link name="link1">
    <inertial>
	<mass value="1.0"/>
	<inertia ixx="0.1" ixy="0.0" ixz="0.0" iyy="0.1" iyz="0.0" izz="0.1"/>
    </inertial>
    <visual>
	<geometry>
	    <cylinder radius="0.05" length="1.0"/>
	</geometry>
    </visual>
</link>
    <!-- More joints and links -->
</robot>
